<?xml version="1.0" ?>
<robot name="eyeglasses3">
	<link name="base_link">
		<visual>
			<origin rpy="0 0 0" xyz="0.0 0.0 0.0"/>
			<geometry>
				<mesh filename="package://part_meshes/base_link.obj" scale="1 1 1"/>
			</geometry>
		</visual>
		<inertial>
			<origin rpy="0 0 0" xyz="0 0 0"/>
			<mass value="0.0"/>
			<inertia ixx="0.0" ixy="0.0" ixz="0.0" iyy="0.0" iyz="0.0" izz="0.0"/>
		</inertial>
	</link>
	<link name="link1">
		<visual>
			<origin rpy="0 0 0" xyz="0.003976 0.007971 -0.061399"/>
			<geometry>
				<mesh filename="package://part_meshes/link1.obj" scale="1 1 1"/>
			</geometry>
		</visual>
		<inertial>
			<origin rpy="0 0 0" xyz="0 0 0"/>
			<mass value="0.0"/>
			<inertia ixx="0.0" ixy="0.0" ixz="0.0" iyy="0.0" iyz="0.0" izz="0.0"/>
		</inertial>
	</link>
	<link name="link2">
		<visual>
			<origin rpy="0 0 0" xyz="0.005248 0.019277 0.06053"/>
			<geometry>
				<mesh filename="package://part_meshes/link2.obj" scale="1 1 1"/>
			</geometry>
		</visual>
		<inertial>
			<origin rpy="0 0 0" xyz="0 0 0"/>
			<mass value="0.0"/>
			<inertia ixx="0.0" ixy="0.0" ixz="0.0" iyy="0.0" iyz="0.0" izz="0.0"/>
		</inertial>
	</link>
	<joint name="joint_base_link-link1" type="revolute">
		<parent link="base_link"/>
		<child link="link1"/>
		<origin xyz="-0.003976 -0.007971 0.061399" rpy="0 0 0"/>
		<axis xyz="1.0 0.0 0.0"/>
		<limit effort="1.0" lower="-0.01" upper="1.5" velocity="1000"/>
	</joint>
	<joint name="joint_base_link-link2" type="revolute">
		<parent link="base_link"/>
		<child link="link2"/>
		<origin xyz="-0.005248 -0.019277 -0.06053" rpy="0 0 0"/>
		<axis xyz="1.0 0.0 0.0"/>
		<limit effort="1.0" lower="-1.5" upper="0.01" velocity="1000"/>
	</joint>
</robot>
